Workbook

Sheet 使い方
B2: 📖 この見積もりファイルの使い方
B3: bravesoft 標準見積もり — 誰でも 3 ステップで金額を動かせます
B5: 1️⃣ 設定 | C5: 「⚙ 設定」シートの青いセルを埋める（単価・管理費率・バッファ・税率・値引き）。ここを変えると全シートの金額が自動で変わります。
B6: 2️⃣ 前提条件 | C6: 「📋 前提条件」シートを埋める（見積根拠・対応範囲・対象外・契約形態・納品物）。金額の前提なので必須。顧客説明ではこのシートを先に提示します（独立シート）。
B7: 3️⃣ 明細と計上✓ | C7: 「見積書」シートの見積明細で工数・担当・項目を調整。金額から外したい行は A 列「計上」を ✓ → － に（プルダウン）。その行はグレーになり、隣の「見積サマリ」・PM費・税込合計・スケジュールまで全部が自動で再計算されます。行を増やすときは既存の明細行をコピーして途中に挿入（一番下の行の下に足さない）。
B9: ⏭ 全体の流れ | C9: ① ⚙ 設定を埋める → ② 📋 前提条件・対象外を埋める → ③ 「見積書」で明細を調整（計上 ✓/－ でスコープ・金額を調整）→ ④ 「見積サマリ」で金額を確認 → ④ 🛡 非機能要件チェックと 🔍 抜け漏れチェックを全部 ✅ に → ⑤ 👤 集計・採算で利益率を確認 → ⑥ 🔔 上長・PM の人間レビュー（Rule 13・必須）→ ⑦ 📤 顧客提出は AI に「提出用の HTML / PDF を生成して」と依頼、または「見積書」の社内列を折りたたんで印刷範囲 A:I を PDF（この Excel は社内用）
C10: 迷ったら AI に聞けば OK。キットは 🧭(開始) 📋(作業開始) ❓(質問) 🧮(試算) 🔔(要レビュー) ✅⏭(完了と次アクション) ⚠️(ブロッカー) 📤(出力) の絵文字で、毎回「次に何をすればいいか」を案内します。
B12: 🎨 色の凡例
C13: うすい水色のセル＝入力欄（自由に変更してよい）
C14: 白いセル＝自動計算や文字の欄。金額の白セルは保護済み（さわらない）。項目名・概要・根拠・担当・計上などの文字欄は白でも編集OK
C15: グレー帯＝小計・集計行
B16: サンプル | C16: グレー文字＋取り消し線の行＝「計上 －」で金額から除外中の行
C17: 紺色＝見出し・強調（入力欄ではない）
C18: 赤いセル＝担当が未入力か、設定の単価表に無い役割（金額が 0 になっています。担当を直してください）
B20: 📊 「見積サマリ」シート | C20: 見積書の隣にある、案件概要＋金額サマリ（フェーズ別の工数・金額税抜、合計税抜/消費税/税込、採算）のシート。見積書と数式連携しているので、明細を直すと自動で更新されます。開いた瞬間に合計が見えるので、下にスクロールする必要はありません。顧客提出は印刷範囲 A:D（採算・社内数字は範囲外）。
B21: 📝 「見積書」シート | C21: 顧客に渡す見積明細。工数・担当・項目を調整し、計上 ✓/－ で金額に反映します。編集はここ、金額の確認は隣の「見積サマリ」で。
B22: 📕 社内列の折りたたみ | C22: 見積書の 社内金額 👤・根拠・優先度(MWO) の列（J〜L）と右側の分析ブロックは『社内グループ』にまとまっています。列の上の [－] ボタンでワンクリックで隠せます。顧客に見せる列（項目〜金額税抜＝A〜I）だけが残るので、印刷範囲 A:I をそのまま PDF にすれば顧客提出物になります（社内の原価・利益率は出ません）。見積サマリも同様に A:D が顧客提出範囲です。
B23: ✓ チェック列（計上） | C23: ✓＝金額に入れる ／ －＝外す。スコープ調整・値引き交渉のときは、行を消さずに － にするのがおすすめ（「やらないこと」が残るので後で戻せる・説明できる）。★スコープ未確定の機能も － のまま一覧に残せます。
B24: 📦 【内訳合計】の親行 | C24: 大きな機能を子行（└）に分解したときの親行。金額・工数は子行の合計が自動で入ります。機能ごと外したいときは、親行ではなく子行（└）すべての計上を － にしてください（親行の合計が自動で 0 になります）。子行を増やすときは子行と子行の間に挿入。
B25: 🧮 PM・全体管理の行 | C25: 工数欄が % になっている行は「そのフェーズの費用 × 率」で自動計算される管理費です。率は設定シートの管理費率と連動。行ごとに数字で上書きもできます（設定連動に戻すには、そのセルに半角で =管理費率 と入力）。
B26: 🔤 優先度（MWO）列 | C26: 金額を動かすいちばん大事な列。M(Must)=必須＝これだけで成立する最小構成 ／ W(Want)=できれば欲しい＝【予算調整の余地】 ／ O(Out)=対象外 ／ ★未確定=要件が固まっていない（0 計上で一覧に残す）。明細右の 💡 ブロックに「M だけの金額」「W の合計（＝いくら削れるか）」が自動集計されるので、予算オーバーのときは ① 💡 で W の合計を見る → ② W の行の計上を － にする、の順で調整します（値引きより先に）。W は青太字・★未確定は赤で表示されます。
B27: 💰 バッファ・体制維持費・値引き | C27: 設定シートで「提示金額にバッファを適用」を ✓ にすると、提示額に係数分が上乗せされます。体制維持費（任意・率）と値引きも設定シートの値が提示額に反映されます。全部「見える行」として金額構成に出ます（Rule 5: 盛りと儲けを隠さない）。
B28: 📚 ことば（これだけ） | C28: 人日＝1 人が 1 営業日（約 8 時間）働く量。3 人日＝1 人なら 3 日。／ 社内単価＝原価（社外秘）・社外単価＝お客様への請求単価。提示額に効くのは社外単価。／ 利益率 2 種＝上段は予定どおり終わった場合、下段はバッファ分まで工数を使い切った場合の最悪ライン。下段がマイナスなら受注前に要相談。
B29: 👤 社内限りマーク | C29: 社内金額・利益率・社内単価は社外に出せません（Rule 10）。このファイルは【社内用】です。顧客提出はキットの提出用 HTML / PDF が標準。Excel で渡す場合は「見積書」の社内列（J〜L と右側ブロック）を折りたたみ、印刷範囲 A:I を PDF 出力してください（社内数字は出ません）。
B30: 📅 スケジュール（動的） | C30: 開始日・並走人数・開始ラグ・審査待ち日数（青セル）を変えると、ガントと総期間が自動で動きます。「工数(人日)」が数式の工程は「見積書」の「見積書」の見積明細と連動しており、明細の工数変更や計上 － でスケジュールも自動で伸縮します。開始ラグを手入力すると、その工程以降の「前の工程が終わったら開始」の自動連結が外れます（並走させたいときだけ上書き。戻すには =前の行のG+前の行のF）。ガントの月列は 18 ヶ月分。超える場合は右に列をコピーしてください。
B31: 📋 前提条件・対象外 | C31: 見積根拠・対応範囲・対象外・契約形態・環境・納品物・検収条件を記録する独立シート（Rule 3）。「ここから外れたら別途お見積もり」の線引きで、あとから揉めないための保険。顧客説明ではまずこのシートを提示し、その後「見積書」で金額の内訳を説明する運びが基本。
... B36: ♻️ 作り直したいとき | C36: このファイルは正本（estimate_master.md）から AI が生成しています。行の大量追加・フェーズ追加は、AI に「見積もり Excel を再生成して」と依頼するのが確実です。

Sheet 設定
A1: ⚙ 見積もり設定（青いセルだけ変更すれば OK）
A3: ■ 案件情報
A4: 案件名 | B4: ○○アプリ / システム開発（案件名に書き換え）
A5: 顧客名（宛先） | B5: 株式会社○○
A6: 作成日 | B6: 46208
A7: 見積有効期限 | B7: =$B$6+30 -> 46238
A8: 見積精度 | B8: 概算 −20%〜+30%
A9: バージョン | B9: 1.0
A10: 作成者 👤（社内用・提出物には出さない） | B10: （作成者名・社内用）
A11: ■ 係数・率（Rule 5: 盛りと儲けを見える化）
A12: 管理費率（PM費） | B12: 0.2 | G12: フェーズ費用に掛ける率。標準 20〜30%（pricing_and_rates.md）
A13: バッファ係数 | B13: 1.2 | G13: 予備工数の係数。標準 1.2x
A14: 提示金額にバッファを適用 | B14: － | G14: ✓ にすると提示額（税抜）に係数分を上乗せ。－ なら精度レンジで吸収
A15: 消費税率 | B15: 0.1 | G15: 標準 10%
A16: 営業日/月 | B16: 20 | G16: 人月換算・スケジュールで使用
A17: 値引き（税抜・正の数で入力） | B17: 0 | G17: 第一候補は値引きでなくスコープ調整（計上チェックを － に）
A18: 体制維持費率（任意） | B18: 0 | G18: 体制を確保して請ける場合に小計へ上乗せする率（例 5%）。不要なら 0%
A19: ■ 単価表（役割別・円/人日） | G19: 社内単価＝原価（👤社内限り・Rule 10）。⚠ 初期値は暫定 — 案件・経理の基準で必ず見直す
A20: 役割キー | B20: 役割名 | C20: 社内単価 👤 | D20: 社外単価 | E20: 人月換算(社外) | F20: 粗利率 👤 | G20: ⚠ 役割キー（A列）は見積明細の「担当」と連動。既存キーは変更しない（表示名を変えたいときは B 列を編集）
A21: PM | B21: プロジェクトマネージャー | C21: 60000 | D21: 75000 | E21: =IF($D21="","",$D21*営業日月) -> 1500000 | F21: =IF(OR($D21="",$D21=0),"",($D21-$C21)/$D21) -> 0.2
A22: Dir | B22: ディレクター | C22: 50000 | D22: 75000 | E22: =IF($D22="","",$D22*営業日月) -> 1500000 | F22: =IF(OR($D22="",$D22=0),"",($D22-$C22)/$D22) -> 0.33333333
A23: SE | B23: システムエンジニア | C23: 60000 | D23: 75000 | E23: =IF($D23="","",$D23*営業日月) -> 1500000 | F23: =IF(OR($D23="",$D23=0),"",($D23-$C23)/$D23) -> 0.2
A24: デザイナー | B24: UI/UXデザイナー | C24: 50000 | D24: 75000 | E24: =IF($D24="","",$D24*営業日月) -> 1500000 | F24: =IF(OR($D24="",$D24=0),"",($D24-$C24)/$D24) -> 0.33333333
A25: アプリ | B25: アプリエンジニア（国内） | C25: 50000 | D25: 75000 | E25: =IF($D25="","",$D25*営業日月) -> 1500000 | F25: =IF(OR($D25="",$D25=0),"",($D25-$C25)/$D25) -> 0.33333333
A26: フロントエンド | B26: フロントエンドエンジニア | C26: 50000 | D26: 75000 | E26: =IF($D26="","",$D26*営業日月) -> 1500000 | F26: =IF(OR($D26="",$D26=0),"",($D26-$C26)/$D26) -> 0.33333333
A27: バックエンド | B27: バックエンドエンジニア | C27: 50000 | D27: 75000 | E27: =IF($D27="","",$D27*営業日月) -> 1500000 | F27: =IF(OR($D27="",$D27=0),"",($D27-$C27)/$D27) -> 0.33333333
A28: オフショア | B28: オフショア開発 | C28: 35000 | D28: 50000 | E28: =IF($D28="","",$D28*営業日月) -> 1000000 | F28: =IF(OR($D28="",$D28=0),"",($D28-$C28)/$D28) -> 0.3
A29: QC | B29: テスト・検証 | C29: 40000 | D29: 60000 | E29: =IF($D29="","",$D29*営業日月) -> 1200000 | F29: =IF(OR($D29="",$D29=0),"",($D29-$C29)/$D29) -> 0.33333333
E30: =IF($D30="","",$D30*営業日月) | F30: =IF(OR($D30="",$D30=0),"",($D30-$C30)/$D30)
A32: ※ 行が足りなければ空行に役割を追記（見積明細の担当プルダウンに自動反映）。
A34: ■ 更新履歴（版管理: 金額や前提を変えたら 1 行残す）
A35: 日付 | B35: 版 | C35: 担当 | D35: 変更内容
A36: 46208 | B36: 1.0 | C36: （作成者名・社内用） | D36: 初版作成（AI 生成）
A41: ⏭ 次にやること: 設定が埋まったら「前提条件」→「見積書」シートへ（青セル以外は自動計算）

Sheet 前提条件
A1: 📋 前提条件・スコープ（Rule 3: この金額の前提。外れたら別途お見積もり）
A2: 青いセルを必ず埋める（AI に依頼して埋めても OK）。顧客説明ではまずこのシートを提示します。特に「対象外」が空だと、後から「それも含まれていると思った」トラブルになります。
A4: ■ 見積根拠（何を基に見積もったか） | B4: お客様ご提供の資料（RFP・機能要望・画面イメージ 等 / YYYY-MM-DD 受領）※受領物に書き換え
A7: ■ 対応範囲（この見積もりに含む工程） | B7: 要件定義 ／ デザイン ／ 設計 ／ 開発 ／ テスト ／ リリース（PM・全体管理を含む）
A10: ■ 対象外（Out of Scope — やらないこと） | B10: 運用・保守（別途契約）
B11: サーバ・ドメイン・ストアアカウント等の実費（お客様ご負担）
B12: 既存システム側の改修（連携 API の追加を除く）
B13: コンテンツ制作・初期データ投入
B14: 多言語対応（ご要望があれば別途お見積もり）
A17: ■ 契約形態 | B17: 請負
A20: ■ 環境（対応 OS・端末・ブラウザ・言語） | B20: iOS / Android 各直近 2 世代・主要端末（Web の場合は主要ブラウザ最新版）
B21: デザインツール: Figma
A24: ■ 納品物 | B24: 要件定義書・画面仕様書・テスト結果報告書・ビルド成果物（ipa / apk）※納品形態に合わせ調整
A27: ■ 検収条件 | B27: 納品後 10 営業日以内に検収
A30: ■ ソースコードの扱い | B30: 原則非納品（要協議）
A33: ■ その他の前提 | B33: ここに示す前提から異なる場合は、別途お見積もりが必要となります。
A36: ⏭ 次にやること: 全セクションを埋めたら「見積書」へ。対象外に迷ったら AI に「この案件の対象外の候補を挙げて」と依頼

Sheet 見積サマリ
B1: ="御見積書｜"&設定!$B$4&"" -> 御見積書｜○○アプリ / システム開発（案件名に書き換え）
B2: =設定!$B$5&" 御中" -> 株式会社○○ 御中
B3: ="作成日: "&TEXT(設定!$B$6,"yyyy/mm/dd")&" 有効期限: "&TEXT(設定!$B$7,"yyyy/mm/dd")&" 見積精度: "&設定!$B$8&" Ver."&設定!$B$9 -> 作成日: 2026/07/05 有効期限: 2026/08/04 見積精度: 概算 −20%〜+30% Ver.1.0
B4: このシートは見積書と自動連携。顧客提出は印刷範囲 A:D（F 列＝社内金額・利益率は折りたたみ／出力外）。
B6: 📋 案件概要
B7: 案件名 | C7: =設定!$B$4 -> ○○アプリ / システム開発（案件名に書き換え）
B8: 宛先 | C8: =設定!$B$5&" 御中" -> 株式会社○○ 御中
B9: 契約形態 | C9: =IF(前提条件!$B17="","（前提条件シートに記入）",前提条件!$B17) -> 請負
B10: 対応範囲 | C10: =IF(前提条件!$B7="","（前提条件シートに記入）",前提条件!$B7) -> 要件定義 ／ デザイン ／ 設計 ／ 開発 ／ テスト ／ リリース（PM・全体管理を含む）
B11: 主な対象外 | C11: =IF(前提条件!$B10="","（前提条件シートに記入）",前提条件!$B10) -> 運用・保守（別途契約）
B12: 作成日 / 有効期限 | C12: =TEXT(設定!$B$6,"yyyy/mm/dd")&" 〜 "&TEXT(設定!$B$7,"yyyy/mm/dd") -> 2026/07/05 〜 2026/08/04
B13: 見積精度 | C13: =設定!$B$8 -> 概算 −20%〜+30%
B15: 📊 お見積もりサマリ（見積書と自動連携） | F15: 👤 社内金額・利益率は社内限り（Rule 10）
B16: 区分 | C16: 工数(人日) | D16: 金額(税抜) | F16: 社内金額 👤 | G16: 利益率 👤
B17: プロジェクト全体 | C17: =SUMIFS(見積書!$G:$G,見積書!$BH:$BH,"leaf",見積書!$A:$A,"<>－") -> 190 | D17: =SUMIFS(見積書!$I:$I,見積書!$BH:$BH,"leaf",見積書!$A:$A,"<>－")+SUMIFS(見積書!$I:$I,見積書!$BH:$BH,"pm",見積書!$A:$A,"<>－") -> 15270000 | F17: =SUMIFS(見積書!$J:$J,見積書!$BH:$BH,"leaf",見積書!$A:$A,"<>－")+SUMIFS(見積書!$J:$J,見積書!$BH:$BH,"pm",見積書!$A:$A,"<>－") -> 11004000 | G17: =IFERROR((D17-F17)/D17,"") -> 0.27937132
B18: 要件定義 | C18: =SUMIFS(見積書!$G:$G,見積書!$BH:$BH,"leaf",見積書!$A:$A,"<>－",見積書!$B:$B,"要件定義") -> 25 | D18: =SUMIFS(見積書!$I:$I,見積書!$BH:$BH,"leaf",見積書!$A:$A,"<>－",見積書!$B:$B,"要件定義")+SUMIFS(見積書!$I:$I,見積書!$BH:$BH,"pm",見積書!$A:$A,"<>－",見積書!$B:$B,"要件定義") -> 2250000 | F18: =SUMIFS(見積書!$J:$J,見積書!$BH:$BH,"leaf",見積書!$A:$A,"<>－",見積書!$B:$B,"要件定義")+SUMIFS(見積書!$J:$J,見積書!$BH:$BH,"pm",見積書!$A:$A,"<>－",見積書!$B:$B,"要件定義") -> 1800000 | G18: =IFERROR((D18-F18)/D18,"") -> 0.2
B19: デザイン | C19: =SUMIFS(見積書!$G:$G,見積書!$BH:$BH,"leaf",見積書!$A:$A,"<>－",見積書!$B:$B,"デザイン") -> 31 | D19: =SUMIFS(見積書!$I:$I,見積書!$BH:$BH,"leaf",見積書!$A:$A,"<>－",見積書!$B:$B,"デザイン")+SUMIFS(見積書!$I:$I,見積書!$BH:$BH,"pm",見積書!$A:$A,"<>－",見積書!$B:$B,"デザイン") -> 2790000 | F19: =SUMIFS(見積書!$J:$J,見積書!$BH:$BH,"leaf",見積書!$A:$A,"<>－",見積書!$B:$B,"デザイン")+SUMIFS(見積書!$J:$J,見積書!$BH:$BH,"pm",見積書!$A:$A,"<>－",見積書!$B:$B,"デザイン") -> 1860000 | G19: =IFERROR((D19-F19)/D19,"") -> 0.33333333
B20: 設計 | C20: =SUMIFS(見積書!$G:$G,見積書!$BH:$BH,"leaf",見積書!$A:$A,"<>－",見積書!$B:$B,"設計") -> 31 | D20: =SUMIFS(見積書!$I:$I,見積書!$BH:$BH,"leaf",見積書!$A:$A,"<>－",見積書!$B:$B,"設計")+SUMIFS(見積書!$I:$I,見積書!$BH:$BH,"pm",見積書!$A:$A,"<>－",見積書!$B:$B,"設計") -> 2790000 | F20: =SUMIFS(見積書!$J:$J,見積書!$BH:$BH,"leaf",見積書!$A:$A,"<>－",見積書!$B:$B,"設計")+SUMIFS(見積書!$J:$J,見積書!$BH:$BH,"pm",見積書!$A:$A,"<>－",見積書!$B:$B,"設計") -> 2076000 | G20: =IFERROR((D20-F20)/D20,"") -> 0.25591398
B21: 開発 | C21: =SUMIFS(見積書!$G:$G,見積書!$BH:$BH,"leaf",見積書!$A:$A,"<>－",見積書!$B:$B,"開発") -> 69 | D21: =SUMIFS(見積書!$I:$I,見積書!$BH:$BH,"leaf",見積書!$A:$A,"<>－",見積書!$B:$B,"開発")+SUMIFS(見積書!$I:$I,見積書!$BH:$BH,"pm",見積書!$A:$A,"<>－",見積書!$B:$B,"開発") -> 4830000 | F21: =SUMIFS(見積書!$J:$J,見積書!$BH:$BH,"leaf",見積書!$A:$A,"<>－",見積書!$B:$B,"開発")+SUMIFS(見積書!$J:$J,見積書!$BH:$BH,"pm",見積書!$A:$A,"<>－",見積書!$B:$B,"開発") -> 3372000 | G21: =IFERROR((D21-F21)/D21,"") -> 0.30186335
B22: テスト | C22: =SUMIFS(見積書!$G:$G,見積書!$BH:$BH,"leaf",見積書!$A:$A,"<>－",見積書!$B:$B,"テスト") -> 28 | D22: =SUMIFS(見積書!$I:$I,見積書!$BH:$BH,"leaf",見積書!$A:$A,"<>－",見積書!$B:$B,"テスト")+SUMIFS(見積書!$I:$I,見積書!$BH:$BH,"pm",見積書!$A:$A,"<>－",見積書!$B:$B,"テスト") -> 2160000 | F22: =SUMIFS(見積書!$J:$J,見積書!$BH:$BH,"leaf",見積書!$A:$A,"<>－",見積書!$B:$B,"テスト")+SUMIFS(見積書!$J:$J,見積書!$BH:$BH,"pm",見積書!$A:$A,"<>－",見積書!$B:$B,"テスト") -> 1536000 | G22: =IFERROR((D22-F22)/D22,"") -> 0.28888889
B23: リリース | C23: =SUMIFS(見積書!$G:$G,見積書!$BH:$BH,"leaf",見積書!$A:$A,"<>－",見積書!$B:$B,"リリース") -> 6 | D23: =SUMIFS(見積書!$I:$I,見積書!$BH:$BH,"leaf",見積書!$A:$A,"<>－",見積書!$B:$B,"リリース")+SUMIFS(見積書!$I:$I,見積書!$BH:$BH,"pm",見積書!$A:$A,"<>－",見積書!$B:$B,"リリース") -> 450000 | F23: =SUMIFS(見積書!$J:$J,見積書!$BH:$BH,"leaf",見積書!$A:$A,"<>－",見積書!$B:$B,"リリース")+SUMIFS(見積書!$J:$J,見積書!$BH:$BH,"pm",見積書!$A:$A,"<>－",見積書!$B:$B,"リリース") -> 360000 | G23: =IFERROR((D23-F23)/D23,"") -> 0.2
B25: 明細小計（社外） | D25: =D17 -> 15270000
B26: リスクバッファ（適用時のみ） | D26: =IF(バッファ適用="✓",ROUND(D17*(バッファ係数-1),0),0) -> 0
B27: 体制維持費（率×小計） | D27: =ROUND(D17*体制維持費率,0) -> 0
B28: お値引き | D28: =-値引き -> 0
B29: ご提示額（税抜） | D29: =SUM(D25:D28) -> 15270000
B30: ="消費税（"&TEXT(税率,"0%")&"）" -> 消費税（10%） | D30: =ROUND(D29*税率,0) -> 1527000
B31: ご提示額（税込） | D31: =D29+D30 -> 16797000
B33: 👤 採算（社内限り・印刷範囲外）
B34: 利益率（工数どおり） | D34: =IFERROR((D29-F17)/D29,"") -> 0.27937132
B35: 利益率（バッファまで消化） | D35: =IFERROR((D29-F17*バッファ係数)/D29,"") -> 0.13524558
B37: ⏭ 次にやること: 金額を確認 → 🔔 上長・PM のレビュー（Rule 13）→ 📤 顧客提出は AI に「提出用の HTML / PDF を生成して」と依頼（or A:D を PDF）

Sheet 見積書
A1: ="御見積書｜"&設定!$B$4&"" -> 御見積書｜○○アプリ / システム開発（案件名に書き換え）
A2: =設定!$B$5&" 御中" -> 株式会社○○ 御中
A3: ="作成日: "&TEXT(設定!$B$6,"yyyy/mm/dd")&" 有効期限: "&TEXT(設定!$B$7,"yyyy/mm/dd")&" 見積精度: "&設定!$B$8&" Ver."&設定!$B$9 -> 作成日: 2026/07/05 有効期限: 2026/08/04 見積精度: 概算 −20%〜+30% Ver.1.0
A4: ⚠ 社内用（J列＝社内金額・右側＝採算/利益率を含む）。このファイルのままお客様へ送らないこと。顧客提出はキットの HTML / PDF、または「社内列」を折りたたんで印刷範囲 A:I を PDF 出力（Rule 10）。
A6: 📝 見積明細（工数×単価の積み上げ・計上✓で金額に反映） | J6: 👤 社内金額は社内限り（Rule 10）／合計・サマリは隣の「見積サマリ」シート
A7: 計上 | B7: フェーズ | C7: カテゴリ | D7: 項目 | E7: 概要 | F7: 実装方式 | G7: 工数(人日) | H7: 担当 | I7: 金額(税抜) | J7: 社内金額 👤 | K7: 根拠・備考 | L7: 優先度(MWO) | N7: 💡 優先度（MWO）別の金額 — 予算調整はここを見る 👤 | BH7: 行種別 | BI7: leaf社内 | BJ7: leaf社外
A8: ✓ | B8: 要件定義 | C8: PM・全体管理 | D8: 要件定義管理 | E8: 進捗・課題・リスク・変更管理（フェーズ費用×管理費率で自動計算） | F8: － | G8: =管理費率 -> 0.2 | H8: － | I8: =IF($A8="－",0,ROUND(SUMIFS($BJ:$BJ,$B:$B,$B8)*$G8,0)) -> 375000 | J8: =IF($A8="－",0,ROUND(SUMIFS($BI:$BI,$B:$B,$B8)*$G8,0)) -> 300000 | N8: 区分 | O8: 工数(計上分) | Q8: 社外金額 | BH8: pm
A9: ✓ | B9: 要件定義 | C9: 要件定義 | D9: プロジェクト計画書 | E9: 目的・スコープ・体制・スケジュール・コミュニケーションルールの定義 | F9: － | G9: 3 | H9: PM | I9: =IF(OR($A9="－",$H9=""),0,IFERROR(ROUND($G9*VLOOKUP($H9,単価表,4,FALSE()),0),0)) -> 225000 | J9: =IF(OR($A9="－",$H9=""),0,IFERROR(ROUND($G9*VLOOKUP($H9,単価表,3,FALSE()),0),0)) -> 180000 | K9: 標準成果物 | L9: M | N9: M（必須＝最小構成） | O9: =SUMIFS($G:$G,$L:$L,"M",$BH:$BH,"leaf",$A:$A,"<>－") -> 162 | Q9: =SUMIFS($I:$I,$L:$L,"M",$BH:$BH,"leaf",$A:$A,"<>－") -> 11075000 | BH9: leaf | BI9: =$J9 -> 180000 | BJ9: =$I9 -> 225000
A10: ✓ | B10: 要件定義 | C10: 要件定義 | D10: キックオフ・要件確定ヒアリング | E10: お客様との要件確定 MTG（複数回想定）・議事録・要件確定書 | F10: － | G10: 4 | H10: PM | I10: =IF(OR($A10="－",$H10=""),0,IFERROR(ROUND($G10*VLOOKUP($H10,単価表,4,FALSE()),0),0)) -> 300000 | J10: =IF(OR($A10="－",$H10=""),0,IFERROR(ROUND($G10*VLOOKUP($H10,単価表,3,FALSE()),0),0)) -> 240000 | K10: 打合せ 4 回想定 | L10: M | N10: W（できれば＝調整余地） | O10: =SUMIFS($G:$G,$L:$L,"W",$BH:$BH,"leaf",$A:$A,"<>－") -> 28 | Q10: =SUMIFS($I:$I,$L:$L,"W",$BH:$BH,"leaf",$A:$A,"<>－") -> 1725000 | BH10: leaf | BI10: =$J10 -> 240000 | BJ10: =$I10 -> 300000
A11: ✓ | B11: 要件定義 | C11: 要件定義 | D11: 業務フロー・As-Is/To-Be 整理 | E11: 現状業務と導入後の流れの整理 | F11: － | G11: 5 | H11: SE | I11: =IF(OR($A11="－",$H11=""),0,IFERROR(ROUND($G11*VLOOKUP($H11,単価表,4,FALSE()),0),0)) -> 375000 | J11: =IF(OR($A11="－",$H11=""),0,IFERROR(ROUND($G11*VLOOKUP($H11,単価表,3,FALSE()),0),0)) -> 300000 | K11: 業務規模より | L11: M | N11: O・★未確定（0円のはず） | Q11: =IF(COUNTIFS($L:$L,"O",$A:$A,"<>－",$I:$I,">0")+COUNTIFS($L:$L,"★未確定",$A:$A,"<>－",$I:$I,">0")=0,"✅ 金額混入なし","⚠ 金額が入っている行あり") -> ✅ 金額混入なし | BH11: leaf | BI11: =$J11 -> 300000 | BJ11: =$I11 -> 375000
A12: ✓ | B12: 要件定義 | C12: 要件定義 | D12: 機能一覧・スコープ定義 | E12: Must / Want / Out of Scope の明文化 | F12: － | G12: 5 | H12: SE | I12: =IF(OR($A12="－",$H12=""),0,IFERROR(ROUND($G12*VLOOKUP($H12,単価表,4,FALSE()),0),0)) -> 375000 | J12: =IF(OR($A12="－",$H12=""),0,IFERROR(ROUND($G12*VLOOKUP($H12,単価表,3,FALSE()),0),0)) -> 300000 | K12: 画面・機能数より | L12: M | BH12: leaf | BI12: =$J12 -> 300000 | BJ12: =$I12 -> 375000
A13: ✓ | B13: 要件定義 | C13: 要件定義 | D13: 要件定義書（機能/非機能） | E13: 機能要件と非機能要件（性能・セキュリティ等）の定義 | F13: － | G13: 8 | H13: SE | I13: =IF(OR($A13="－",$H13=""),0,IFERROR(ROUND($G13*VLOOKUP($H13,単価表,4,FALSE()),0),0)) -> 600000 | J13: =IF(OR($A13="－",$H13=""),0,IFERROR(ROUND($G13*VLOOKUP($H13,単価表,3,FALSE()),0),0)) -> 480000 | K13: 画面・機能数より | L13: M | N13: 🔍 抜け漏れチェック（Rule 2・自動判定）👤 | BH13: leaf | BI13: =$J13 -> 480000 | BJ13: =$I13 -> 600000
A14: ✓ | B14: デザイン | C14: PM・全体管理 | D14: デザイン管理 | E14: デザインフェーズの進捗・品質管理 | F14: － | G14: =管理費率 -> 0.2 | H14: － | I14: =IF($A14="－",0,ROUND(SUMIFS($BJ:$BJ,$B:$B,$B14)*$G14,0)) -> 465000 | J14: =IF($A14="－",0,ROUND(SUMIFS($BI:$BI,$B:$B,$B14)*$G14,0)) -> 310000 | N14: PM・全体管理 | Q14: =IF(SUMIFS($I:$I,$BH:$BH,"pm",$A:$A,"<>－")>0,"✅ 計上あり","⚠ 未計上") -> ✅ 計上あり | BH14: pm
A15: ✓ | B15: デザイン | C15: UI/UXデザイン | D15: ワイヤーフレーム | E15: 主要画面の構成・導線設計 | F15: － | G15: 8 | H15: デザイナー | I15: =IF(OR($A15="－",$H15=""),0,IFERROR(ROUND($G15*VLOOKUP($H15,単価表,4,FALSE()),0),0)) -> 600000 | J15: =IF(OR($A15="－",$H15=""),0,IFERROR(ROUND($G15*VLOOKUP($H15,単価表,3,FALSE()),0),0)) -> 400000 | K15: 画面数より | L15: M | N15: テスト工程 | Q15: =IF(SUMIFS($I:$I,$B:$B,"*テスト*",$BH:$BH,"leaf",$A:$A,"<>－")+SUMIFS($I:$I,$C:$C,"*テスト*",$BH:$BH,"leaf",$A:$A,"<>－")>0,"✅ 計上あり","⚠ 未計上") -> ✅ 計上あり | BH15: leaf | BI15: =$J15 -> 400000 | BJ15: =$I15 -> 600000
A16: ✓ | B16: デザイン | C16: UI/UXデザイン | D16: UIデザイン（主要画面） | E16: 本デザイン・プロトタイプ | F16: － | G16: 15 | H16: デザイナー | I16: =IF(OR($A16="－",$H16=""),0,IFERROR(ROUND($G16*VLOOKUP($H16,単価表,4,FALSE()),0),0)) -> 1125000 | J16: =IF(OR($A16="－",$H16=""),0,IFERROR(ROUND($G16*VLOOKUP($H16,単価表,3,FALSE()),0),0)) -> 750000 | K16: 画面数×難易度より | L16: M | N16: リリース／ストア申請 | Q16: =IF(SUMIFS($I:$I,$B:$B,"*リリース*",$BH:$BH,"leaf",$A:$A,"<>－")+SUMIFS($I:$I,$D:$D,"*ストア*",$BH:$BH,"leaf",$A:$A,"<>－")+SUMIFS($I:$I,$D:$D,"*リリース*",$BH:$BH,"leaf",$A:$A,"<>－")>0,"✅ 計上あり","⚠ 未計上") -> ✅ 計上あり | BH16: leaf | BI16: =$J16 -> 750000 | BJ16: =$I16 -> 1125000
A17: ✓ | B17: デザイン | C17: UI/UXデザイン | D17: デザインガイドライン・共通パーツ | E17: 色・タイポ・コンポーネントの整備 | F17: － | G17: 4 | H17: デザイナー | I17: =IF(OR($A17="－",$H17=""),0,IFERROR(ROUND($G17*VLOOKUP($H17,単価表,4,FALSE()),0),0)) -> 300000 | J17: =IF(OR($A17="－",$H17=""),0,IFERROR(ROUND($G17*VLOOKUP($H17,単価表,3,FALSE()),0),0)) -> 200000 | K17: 標準 | L17: M | N17: 非機能要件チェック | Q17: =IF(COUNTBLANK(非機能要件チェック!$E$4:$E$32)>0,"⚠ 未判定 "&COUNTBLANK(非機能要件チェック!$E$4:$E$32)&" 件",IF(COUNTIFS(非機能要件チェック!$E$4:$E$32,"対象",非機能要件チェック!$F$4:$F$32,"")+COUNTIF(非機能要件チェック!$E$4:$E$32,"要確認")>0,"⚠ 未反映/要確認あり（シート参照）","✅ チェック済")) -> ⚠ 未判定 29 件 | BH17: leaf | BI17: =$J17 -> 200000 | BJ17: =$I17 -> 300000
A18: ✓ | B18: デザイン | C18: UI/UXデザイン | D18: アプリアイコン・ストア掲載素材 | E18: アイコン・スクリーンショット・紹介文（アプリ案件のみ） | F18: － | G18: 4 | H18: デザイナー | I18: =IF(OR($A18="－",$H18=""),0,IFERROR(ROUND($G18*VLOOKUP($H18,単価表,4,FALSE()),0),0)) -> 300000 | J18: =IF(OR($A18="－",$H18=""),0,IFERROR(ROUND($G18*VLOOKUP($H18,単価表,3,FALSE()),0),0)) -> 200000 | K18: 標準 | L18: W | BH18: leaf | BI18: =$J18 -> 200000 | BJ18: =$I18 -> 300000
A19: ✓ | B19: 設計 | C19: PM・全体管理 | D19: 設計管理 | E19: 設計フェーズの進捗・品質管理 | F19: － | G19: =管理費率 -> 0.2 | H19: － | I19: =IF($A19="－",0,ROUND(SUMIFS($BJ:$BJ,$B:$B,$B19)*$G19,0)) -> 465000 | J19: =IF($A19="－",0,ROUND(SUMIFS($BI:$BI,$B:$B,$B19)*$G19,0)) -> 346000 | N19: 🔍 フェーズ×カテゴリ 工数マトリクス（計上分・人日）— 空欄＝抜け候補 👤 | BH19: pm
A20: ✓ | B20: 設計 | C20: 内部設計 | D20: アーキテクチャ・技術選定 | E20: 構成・フレームワーク・インフラ方針の決定 | F20: － | G20: 5 | H20: SE | I20: =IF(OR($A20="－",$H20=""),0,IFERROR(ROUND($G20*VLOOKUP($H20,単価表,4,FALSE()),0),0)) -> 375000 | J20: =IF(OR($A20="－",$H20=""),0,IFERROR(ROUND($G20*VLOOKUP($H20,単価表,3,FALSE()),0),0)) -> 300000 | K20: 標準 | L20: M | N20: フェーズ＼カテゴリ | O20: 要件定義 | P20: UI/UXデザイン | Q20: 内部設計 | R20: 外部設計 | S20: インフラ・環境 | T20: アプリ(iOS/Android) | U20: API・サーバ | V20: 管理画面(CMS) | W20: バッチ | X20: 外部連携 | Y20: テスト・検証 | Z20: セキュリティ | AA20: 共通 | AB20: 運用・保守 | BH20: leaf | BI20: =$J20 -> 300000 | BJ20: =$I20 -> 375000
A21: ✓ | B21: 設計 | C21: 外部設計 | D21: 画面仕様書 | E21: 表示項目・操作・遷移・エラーの定義 | F21: － | G21: 10 | H21: SE | I21: =IF(OR($A21="－",$H21=""),0,IFERROR(ROUND($G21*VLOOKUP($H21,単価表,4,FALSE()),0),0)) -> 750000 | J21: =IF(OR($A21="－",$H21=""),0,IFERROR(ROUND($G21*VLOOKUP($H21,単価表,3,FALSE()),0),0)) -> 600000 | K21: 画面数より | L21: M | N21: 要件定義 | O21: =SUMIFS($G:$G,$B:$B,"要件定義",$C:$C,"要件定義",$BH:$BH,"leaf",$A:$A,"<>－") -> 25 | P21: =SUMIFS($G:$G,$B:$B,"要件定義",$C:$C,"UI/UXデザイン",$BH:$BH,"leaf",$A:$A,"<>－") -> 0 | Q21: =SUMIFS($G:$G,$B:$B,"要件定義",$C:$C,"内部設計",$BH:$BH,"leaf",$A:$A,"<>－") -> 0 | R21: =SUMIFS($G:$G,$B:$B,"要件定義",$C:$C,"外部設計",$BH:$BH,"leaf",$A:$A,"<>－") -> 0 | S21: =SUMIFS($G:$G,$B:$B,"要件定義",$C:$C,"インフラ・環境",$BH:$BH,"leaf",$A:$A,"<>－") -> 0 | T21: =SUMIFS($G:$G,$B:$B,"要件定義",$C:$C,"アプリ(iOS/Android)",$BH:$BH,"leaf",$A:$A,"<>－") -> 0 | U21: =SUMIFS($G:$G,$B:$B,"要件定義",$C:$C,"API・サーバ",$BH:$BH,"leaf",$A:$A,"<>－") -> 0 | V21: =SUMIFS($G:$G,$B:$B,"要件定義",$C:$C,"管理画面(CMS)",$BH:$BH,"leaf",$A:$A,"<>－") -> 0 | W21: =SUMIFS($G:$G,$B:$B,"要件定義",$C:$C,"バッチ",$BH:$BH,"leaf",$A:$A,"<>－") -> 0 | X21: =SUMIFS($G:$G,$B:$B,"要件定義",$C:$C,"外部連携",$BH:$BH,"leaf",$A:$A,"<>－") -> 0 | Y21: =SUMIFS($G:$G,$B:$B,"要件定義",$C:$C,"テスト・検証",$BH:$BH,"leaf",$A:$A,"<>－") -> 0 | Z21: =SUMIFS($G:$G,$B:$B,"要件定義",$C:$C,"セキュリティ",$BH:$BH,"leaf",$A:$A,"<>－") -> 0 | AA21: =SUMIFS($G:$G,$B:$B,"要件定義",$C:$C,"共通",$BH:$BH,"leaf",$A:$A,"<>－") -> 0 | AB21: =SUMIFS($G:$G,$B:$B,"要件定義",$C:$C,"運用・保守",$BH:$BH,"leaf",$A:$A,"<>－") -> 0 | BH21: leaf | BI21: =$J21 -> 600000 | BJ21: =$I21 -> 750000
A22: ✓ | B22: 設計 | C22: 外部設計 | D22: API・インターフェース設計 | E22: エンドポイント・リクエスト/レスポンス定義 | F22: － | G22: 8 | H22: バックエンド | I22: =IF(OR($A22="－",$H22=""),0,IFERROR(ROUND($G22*VLOOKUP($H22,単価表,4,FALSE()),0),0)) -> 600000 | J22: =IF(OR($A22="－",$H22=""),0,IFERROR(ROUND($G22*VLOOKUP($H22,単価表,3,FALSE()),0),0)) -> 400000 | K22: API 本数より | L22: M | N22: デザイン | O22: =SUMIFS($G:$G,$B:$B,"デザイン",$C:$C,"要件定義",$BH:$BH,"leaf",$A:$A,"<>－") -> 0 | P22: =SUMIFS($G:$G,$B:$B,"デザイン",$C:$C,"UI/UXデザイン",$BH:$BH,"leaf",$A:$A,"<>－") -> 31 | Q22: =SUMIFS($G:$G,$B:$B,"デザイン",$C:$C,"内部設計",$BH:$BH,"leaf",$A:$A,"<>－") -> 0 | R22: =SUMIFS($G:$G,$B:$B,"デザイン",$C:$C,"外部設計",$BH:$BH,"leaf",$A:$A,"<>－") -> 0 | S22: =SUMIFS($G:$G,$B:$B,"デザイン",$C:$C,"インフラ・環境",$BH:$BH,"leaf",$A:$A,"<>－") -> 0 | T22: =SUMIFS($G:$G,$B:$B,"デザイン",$C:$C,"アプリ(iOS/Android)",$BH:$BH,"leaf",$A:$A,"<>－") -> 0 | U22: =SUMIFS($G:$G,$B:$B,"デザイン",$C:$C,"API・サーバ",$BH:$BH,"leaf",$A:$A,"<>－") -> 0 | V22: =SUMIFS($G:$G,$B:$B,"デザイン",$C:$C,"管理画面(CMS)",$BH:$BH,"leaf",$A:$A,"<>－") -> 0 | W22: =SUMIFS($G:$G,$B:$B,"デザイン",$C:$C,"バッチ",$BH:$BH,"leaf",$A:$A,"<>－") -> 0 | X22: =SUMIFS($G:$G,$B:$B,"デザイン",$C:$C,"外部連携",$BH:$BH,"leaf",$A:$A,"<>－") -> 0 | Y22: =SUMIFS($G:$G,$B:$B,"デザイン",$C:$C,"テスト・検証",$BH:$BH,"leaf",$A:$A,"<>－") -> 0 | Z22: =SUMIFS($G:$G,$B:$B,"デザイン",$C:$C,"セキュリティ",$BH:$BH,"leaf",$A:$A,"<>－") -> 0 | AA22: =SUMIFS($G:$G,$B:$B,"デザイン",$C:$C,"共通",$BH:$BH,"leaf",$A:$A,"<>－") -> 0 | AB22: =SUMIFS($G:$G,$B:$B,"デザイン",$C:$C,"運用・保守",$BH:$BH,"leaf",$A:$A,"<>－") -> 0 | BH22: leaf | BI22: =$J22 -> 400000 | BJ22: =$I22 -> 600000
A23: ✓ | B23: 設計 | C23: 内部設計 | D23: DB 設計 | E23: テーブル・インデックス・マイグレーション方針 | F23: － | G23: 5 | H23: バックエンド | I23: =IF(OR($A23="－",$H23=""),0,IFERROR(ROUND($G23*VLOOKUP($H23,単価表,4,FALSE()),0),0)) -> 375000 | J23: =IF(OR($A23="－",$H23=""),0,IFERROR(ROUND($G23*VLOOKUP($H23,単価表,3,FALSE()),0),0)) -> 250000 | K23: テーブル数より | L23: M | N23: 設計 | O23: =SUMIFS($G:$G,$B:$B,"設計",$C:$C,"要件定義",$BH:$BH,"leaf",$A:$A,"<>－") -> 0 | P23: =SUMIFS($G:$G,$B:$B,"設計",$C:$C,"UI/UXデザイン",$BH:$BH,"leaf",$A:$A,"<>－") -> 0 | Q23: =SUMIFS($G:$G,$B:$B,"設計",$C:$C,"内部設計",$BH:$BH,"leaf",$A:$A,"<>－") -> 10 | R23: =SUMIFS($G:$G,$B:$B,"設計",$C:$C,"外部設計",$BH:$BH,"leaf",$A:$A,"<>－") -> 21 | S23: =SUMIFS($G:$G,$B:$B,"設計",$C:$C,"インフラ・環境",$BH:$BH,"leaf",$A:$A,"<>－") -> 0 | T23: =SUMIFS($G:$G,$B:$B,"設計",$C:$C,"アプリ(iOS/Android)",$BH:$BH,"leaf",$A:$A,"<>－") -> 0 | U23: =SUMIFS($G:$G,$B:$B,"設計",$C:$C,"API・サーバ",$BH:$BH,"leaf",$A:$A,"<>－") -> 0 | V23: =SUMIFS($G:$G,$B:$B,"設計",$C:$C,"管理画面(CMS)",$BH:$BH,"leaf",$A:$A,"<>－") -> 0 | W23: =SUMIFS($G:$G,$B:$B,"設計",$C:$C,"バッチ",$BH:$BH,"leaf",$A:$A,"<>－") -> 0 | X23: =SUMIFS($G:$G,$B:$B,"設計",$C:$C,"外部連携",$BH:$BH,"leaf",$A:$A,"<>－") -> 0 | Y23: =SUMIFS($G:$G,$B:$B,"設計",$C:$C,"テスト・検証",$BH:$BH,"leaf",$A:$A,"<>－") -> 0 | Z23: =SUMIFS($G:$G,$B:$B,"設計",$C:$C,"セキュリティ",$BH:$BH,"leaf",$A:$A,"<>－") -> 0 | AA23: =SUMIFS($G:$G,$B:$B,"設計",$C:$C,"共通",$BH:$BH,"leaf",$A:$A,"<>－") -> 0 | AB23: =SUMIFS($G:$G,$B:$B,"設計",$C:$C,"運用・保守",$BH:$BH,"leaf",$A:$A,"<>－") -> 0 | BH23: leaf | BI23: =$J23 -> 250000 | BJ23: =$I23 -> 375000
A24: ✓ | B24: 設計 | C24: 外部設計 | D24: エラー・例外設計 | E24: エラーコード体系とユーザー向けメッセージの定義 | F24: － | G24: 3 | H24: SE | I24: =IF(OR($A24="－",$H24=""),0,IFERROR(ROUND($G24*VLOOKUP($H24,単価表,4,FALSE()),0),0)) -> 225000 | J24: =IF(OR($A24="－",$H24=""),0,IFERROR(ROUND($G24*VLOOKUP($H24,単価表,3,FALSE()),0),0)) -> 180000 | K24: 標準 | L24: M | N24: 開発 | O24: =SUMIFS($G:$G,$B:$B,"開発",$C:$C,"要件定義",$BH:$BH,"leaf",$A:$A,"<>－") -> 0 | P24: =SUMIFS($G:$G,$B:$B,"開発",$C:$C,"UI/UXデザイン",$BH:$BH,"leaf",$A:$A,"<>－") -> 0 | Q24: =SUMIFS($G:$G,$B:$B,"開発",$C:$C,"内部設計",$BH:$BH,"leaf",$A:$A,"<>－") -> 0 | R24: =SUMIFS($G:$G,$B:$B,"開発",$C:$C,"外部設計",$BH:$BH,"leaf",$A:$A,"<>－") -> 0 | S24: =SUMIFS($G:$G,$B:$B,"開発",$C:$C,"インフラ・環境",$BH:$BH,"leaf",$A:$A,"<>－") -> 5 | T24: =SUMIFS($G:$G,$B:$B,"開発",$C:$C,"アプリ(iOS/Android)",$BH:$BH,"leaf",$A:$A,"<>－") -> 36 | U24: =SUMIFS($G:$G,$B:$B,"開発",$C:$C,"API・サーバ",$BH:$BH,"leaf",$A:$A,"<>－") -> 15 | V24: =SUMIFS($G:$G,$B:$B,"開発",$C:$C,"管理画面(CMS)",$BH:$BH,"leaf",$A:$A,"<>－") -> 10 | W24: =SUMIFS($G:$G,$B:$B,"開発",$C:$C,"バッチ",$BH:$BH,"leaf",$A:$A,"<>－") -> 3 | X24: =SUMIFS($G:$G,$B:$B,"開発",$C:$C,"外部連携",$BH:$BH,"leaf",$A:$A,"<>－") -> 0 | Y24: =SUMIFS($G:$G,$B:$B,"開発",$C:$C,"テスト・検証",$BH:$BH,"leaf",$A:$A,"<>－") -> 0 | Z24: =SUMIFS($G:$G,$B:$B,"開発",$C:$C,"セキュリティ",$BH:$BH,"leaf",$A:$A,"<>－") -> 0 | AA24: =SUMIFS($G:$G,$B:$B,"開発",$C:$C,"共通",$BH:$BH,"leaf",$A:$A,"<>－") -> 0 | AB24: =SUMIFS($G:$G,$B:$B,"開発",$C:$C,"運用・保守",$BH:$BH,"leaf",$A:$A,"<>－") -> 0 | BH24: leaf | BI24: =$J24 -> 180000 | BJ24: =$I24 -> 225000
A25: ✓ | B25: 開発 | C25: PM・全体管理 | D25: 開発管理 | E25: 開発フェーズの進捗・品質・リスク管理（オフショア連携含む） | F25: － | G25: =管理費率 -> 0.2 | H25: － | I25: =IF($A25="－",0,ROUND(SUMIFS($BJ:$BJ,$B:$B,$B25)*$G25,0)) -> 805000 | J25: =IF($A25="－",0,ROUND(SUMIFS($BI:$BI,$B:$B,$B25)*$G25,0)) -> 562000 | N25: テスト | O25: =SUMIFS($G:$G,$B:$B,"テスト",$C:$C,"要件定義",$BH:$BH,"leaf",$A:$A,"<>－") -> 0 | P25: =SUMIFS($G:$G,$B:$B,"テスト",$C:$C,"UI/UXデザイン",$BH:$BH,"leaf",$A:$A,"<>－") -> 0 | Q25: =SUMIFS($G:$G,$B:$B,"テスト",$C:$C,"内部設計",$BH:$BH,"leaf",$A:$A,"<>－") -> 0 | R25: =SUMIFS($G:$G,$B:$B,"テスト",$C:$C,"外部設計",$BH:$BH,"leaf",$A:$A,"<>－") -> 0 | S25: =SUMIFS($G:$G,$B:$B,"テスト",$C:$C,"インフラ・環境",$BH:$BH,"leaf",$A:$A,"<>－") -> 0 | T25: =SUMIFS($G:$G,$B:$B,"テスト",$C:$C,"アプリ(iOS/Android)",$BH:$BH,"leaf",$A:$A,"<>－") -> 0 | U25: =SUMIFS($G:$G,$B:$B,"テスト",$C:$C,"API・サーバ",$BH:$BH,"leaf",$A:$A,"<>－") -> 0 | V25: =SUMIFS($G:$G,$B:$B,"テスト",$C:$C,"管理画面(CMS)",$BH:$BH,"leaf",$A:$A,"<>－") -> 0 | W25: =SUMIFS($G:$G,$B:$B,"テスト",$C:$C,"バッチ",$BH:$BH,"leaf",$A:$A,"<>－") -> 0 | X25: =SUMIFS($G:$G,$B:$B,"テスト",$C:$C,"外部連携",$BH:$BH,"leaf",$A:$A,"<>－") -> 0 | Y25: =SUMIFS($G:$G,$B:$B,"テスト",$C:$C,"テスト・検証",$BH:$BH,"leaf",$A:$A,"<>－") -> 25 | Z25: =SUMIFS($G:$G,$B:$B,"テスト",$C:$C,"セキュリティ",$BH:$BH,"leaf",$A:$A,"<>－") -> 3 | AA25: =SUMIFS($G:$G,$B:$B,"テスト",$C:$C,"共通",$BH:$BH,"leaf",$A:$A,"<>－") -> 0 | AB25: =SUMIFS($G:$G,$B:$B,"テスト",$C:$C,"運用・保守",$BH:$BH,"leaf",$A:$A,"<>－") -> 0 | BH25: pm
A26: ✓ | B26: 開発 | C26: インフラ・環境 | D26: 開発環境構築・CI/CD | E26: リポジトリ・ビルド・テスト配布環境の整備 | F26: 共通 | G26: 5 | H26: SE | I26: =IF(OR($A26="－",$H26=""),0,IFERROR(ROUND($G26*VLOOKUP($H26,単価表,4,FALSE()),0),0)) -> 375000 | J26: =IF(OR($A26="－",$H26=""),0,IFERROR(ROUND($G26*VLOOKUP($H26,単価表,3,FALSE()),0),0)) -> 300000 | K26: 標準構成 | L26: M | N26: リリース | O26: =SUMIFS($G:$G,$B:$B,"リリース",$C:$C,"要件定義",$BH:$BH,"leaf",$A:$A,"<>－") -> 0 | P26: =SUMIFS($G:$G,$B:$B,"リリース",$C:$C,"UI/UXデザイン",$BH:$BH,"leaf",$A:$A,"<>－") -> 0 | Q26: =SUMIFS($G:$G,$B:$B,"リリース",$C:$C,"内部設計",$BH:$BH,"leaf",$A:$A,"<>－") -> 0 | R26: =SUMIFS($G:$G,$B:$B,"リリース",$C:$C,"外部設計",$BH:$BH,"leaf",$A:$A,"<>－") -> 0 | S26: =SUMIFS($G:$G,$B:$B,"リリース",$C:$C,"インフラ・環境",$BH:$BH,"leaf",$A:$A,"<>－") -> 0 | T26: =SUMIFS($G:$G,$B:$B,"リリース",$C:$C,"アプリ(iOS/Android)",$BH:$BH,"leaf",$A:$A,"<>－") -> 0 | U26: =SUMIFS($G:$G,$B:$B,"リリース",$C:$C,"API・サーバ",$BH:$BH,"leaf",$A:$A,"<>－") -> 0 | V26: =SUMIFS($G:$G,$B:$B,"リリース",$C:$C,"管理画面(CMS)",$BH:$BH,"leaf",$A:$A,"<>－") -> 0 | W26: =SUMIFS($G:$G,$B:$B,"リリース",$C:$C,"バッチ",$BH:$BH,"leaf",$A:$A,"<>－") -> 0 | X26: =SUMIFS($G:$G,$B:$B,"リリース",$C:$C,"外部連携",$BH:$BH,"leaf",$A:$A,"<>－") -> 0 | Y26: =SUMIFS($G:$G,$B:$B,"リリース",$C:$C,"テスト・検証",$BH:$BH,"leaf",$A:$A,"<>－") -> 0 | Z26: =SUMIFS($G:$G,$B:$B,"リリース",$C:$C,"セキュリティ",$BH:$BH,"leaf",$A:$A,"<>－") -> 0 | AA26: =SUMIFS($G:$G,$B:$B,"リリース",$C:$C,"共通",$BH:$BH,"leaf",$A:$A,"<>－") -> 3 | AB26: =SUMIFS($G:$G,$B:$B,"リリース",$C:$C,"運用・保守",$BH:$BH,"leaf",$A:$A,"<>－") -> 3 | BH26: leaf | BI26: =$J26 -> 300000 | BJ26: =$I26 -> 375000
B27: 開発 | C27: アプリ(iOS/Android) | D27: 認証・ログイン機能【内訳合計】 | E27: ログイン・トークン管理・パスワード再設定を含む認証一式 | F27: － | G27: =SUMIFS(G28:G30,A28:A30,"<>－") -> 8 | H27: － | I27: =SUM(I28:I30) -> 400000 | J27: =SUM(J28:J30) -> 280000 | BH27: parent
A28: ✓ | B28: 開発 | C28: アプリ(iOS/Android) | D28: └ ログイン画面 UI・入力チェック | E28: バリデーション・パスワード表示切替 | F28: ネイティブ | G28: 2 | H28: オフショア | I28: =IF(OR($A28="－",$H28=""),0,IFERROR(ROUND($G28*VLOOKUP($H28,単価表,4,FALSE()),0),0)) -> 100000 | J28: =IF(OR($A28="－",$H28=""),0,IFERROR(ROUND($G28*VLOOKUP($H28,単価表,3,FALSE()),0),0)) -> 70000 | K28: 標準画面 1 枚 | L28: M | BH28: leaf | BI28: =$J28 -> 70000 | BJ28: =$I28 -> 100000
A29: ✓ | B29: 開発 | C29: アプリ(iOS/Android) | D29: └ 認証 API 連携・トークン管理 | E29: ログイン API・セキュアストレージ・リフレッシュ | F29: ネイティブ | G29: 4 | H29: オフショア | I29: =IF(OR($A29="－",$H29=""),0,IFERROR(ROUND($G29*VLOOKUP($H29,単価表,4,FALSE()),0),0)) -> 200000 | J29: =IF(OR($A29="－",$H29=""),0,IFERROR(ROUND($G29*VLOOKUP($H29,単価表,3,FALSE()),0),0)) -> 140000 | K29: API 2 本＋Keychain/Keystore | L29: M | BH29: leaf | BI29: =$J29 -> 140000 | BJ29: =$I29 -> 200000
A30: ✓ | B30: 開発 | C30: アプリ(iOS/Android) | D30: └ パスワード再設定 | E30: 再設定メール送信・再設定画面 | F30: ネイティブ | G30: 2 | H30: オフショア | I30: =IF(OR($A30="－",$H30=""),0,IFERROR(ROUND($G30*VLOOKUP($H30,単価表,4,FALSE()),0),0)) -> 100000 | J30: =IF(OR($A30="－",$H30=""),0,IFERROR(ROUND($G30*VLOOKUP($H30,単価表,3,FALSE()),0),0)) -> 70000 | K30: 標準フロー | L30: M | BH30: leaf | BI30: =$J30 -> 70000 | BJ30: =$I30 -> 100000
A31: ✓ | B31: 開発 | C31: アプリ(iOS/Android) | D31: ホーム・一覧・詳細画面（※主要機能①に書き換え） | E31: この案件のコア機能に書き換えて使う | F31: ネイティブ | G31: 10 | H31: オフショア | I31: =IF(OR($A31="－",$H31=""),0,IFERROR(ROUND($G31*VLOOKUP($H31,単価表,4,FALSE()),0),0)) -> 500000 | J31: =IF(OR($A31="－",$H31=""),0,IFERROR(ROUND($G31*VLOOKUP($H31,単価表,3,FALSE()),0),0)) -> 350000 | K31: 画面数×難易度より | L31: M | BH31: leaf | BI31: =$J31 -> 350000 | BJ31: =$I31 -> 500000
A32: ✓ | B32: 開発 | C32: アプリ(iOS/Android) | D32: 登録・入力フォーム（※主要機能②に書き換え） | E32: この案件のコア機能に書き換えて使う | F32: ネイティブ | G32: 8 | H32: オフショア | I32: =IF(OR($A32="－",$H32=""),0,IFERROR(ROUND($G32*VLOOKUP($H32,単価表,4,FALSE()),0),0)) -> 400000 | J32: =IF(OR($A32="－",$H32=""),0,IFERROR(ROUND($G32*VLOOKUP($H32,単価表,3,FALSE()),0),0)) -> 280000 | K32: 画面数×難易度より | L32: M | BH32: leaf | BI32: =$J32 -> 280000 | BJ32: =$I32 -> 400000
A33: ✓ | B33: 開発 | C33: アプリ(iOS/Android) | D33: マイページ・設定 | E33: プロフィール・通知設定・利用規約表示 等 | F33: ネイティブ | G33: 5 | H33: オフショア | I33: =IF(OR($A33="－",$H33=""),0,IFERROR(ROUND($G33*VLOOKUP($H33,単価表,4,FALSE()),0),0)) -> 250000 | J33: =IF(OR($A33="－",$H33=""),0,IFERROR(ROUND($G33*VLOOKUP($H33,単価表,3,FALSE()),0),0)) -> 175000 | K33: 標準画面群 | L33: M | BH33: leaf | BI33: =$J33 -> 175000 | BJ33: =$I33 -> 250000
A34: ✓ | B34: 開発 | C34: API・サーバ | D34: API 開発（サーバ側） | E34: アプリ向けエンドポイントの実装 | F34: 共通 | G34: 15 | H34: バックエンド | I34: =IF(OR($A34="－",$H34=""),0,IFERROR(ROUND($G34*VLOOKUP($H34,単価表,4,FALSE()),0),0)) -> 1125000 | J34: =IF(OR($A34="－",$H34=""),0,IFERROR(ROUND($G34*VLOOKUP($H34,単価表,3,FALSE()),0),0)) -> 750000 | K34: エンドポイント数より | L34: M | BH34: leaf | BI34: =$J34 -> 750000 | BJ34: =$I34 -> 1125000
A35: ✓ | B35: 開発 | C35: 管理画面(CMS) | D35: 管理画面（CMS）基本機能 | E35: コンテンツ・ユーザー管理の基本 CRUD | F35: 共通 | G35: 10 | H35: オフショア | I35: =IF(OR($A35="－",$H35=""),0,IFERROR(ROUND($G35*VLOOKUP($H35,単価表,4,FALSE()),0),0)) -> 500000 | J35: =IF(OR($A35="－",$H35=""),0,IFERROR(ROUND($G35*VLOOKUP($H35,単価表,3,FALSE()),0),0)) -> 350000 | K35: 管理項目数より | L35: W | BH35: leaf | BI35: =$J35 -> 350000 | BJ35: =$I35 -> 500000
A36: ✓ | B36: 開発 | C36: アプリ(iOS/Android) | D36: プッシュ通知 | E36: 通知受信・一覧・既読管理 | F36: ネイティブ | G36: 5 | H36: オフショア | I36: =IF(OR($A36="－",$H36=""),0,IFERROR(ROUND($G36*VLOOKUP($H36,単価表,4,FALSE()),0),0)) -> 250000 | J36: =IF(OR($A36="－",$H36=""),0,IFERROR(ROUND($G36*VLOOKUP($H36,単価表,3,FALSE()),0),0)) -> 175000 | K36: FCM 標準構成 | L36: W | BH36: leaf | BI36: =$J36 -> 175000 | BJ36: =$I36 -> 250000
A37: ✓ | B37: 開発 | C37: バッチ | D37: バッチ・定期処理 | E37: 集計・通知送信などの定期ジョブ | F37: 共通 | G37: 3 | H37: バックエンド | I37: =IF(OR($A37="－",$H37=""),0,IFERROR(ROUND($G37*VLOOKUP($H37,単価表,4,FALSE()),0),0)) -> 225000 | J37: =IF(OR($A37="－",$H37=""),0,IFERROR(ROUND($G37*VLOOKUP($H37,単価表,3,FALSE()),0),0)) -> 150000 | K37: 本数より | L37: W | BH37: leaf | BI37: =$J37 -> 150000 | BJ37: =$I37 -> 225000
A38: － | B38: 開発 | C38: 外部連携 | D38: 外部サービス連携（決済・地図・SNS 等） | E38: 連携先が確定したら要件を詰めて別途お見積もり | F38: － | G38: 0 | H38: オフショア | I38: =IF(OR($A38="－",$H38=""),0,IFERROR(ROUND($G38*VLOOKUP($H38,単価表,4,FALSE()),0),0)) -> 0 | J38: =IF(OR($A38="－",$H38=""),0,IFERROR(ROUND($G38*VLOOKUP($H38,単価表,3,FALSE()),0),0)) -> 0 | K38: ★スコープ未確定のため 0 計上 | L38: ★未確定 | BH38: leaf | BI38: =$J38 -> 0 | BJ38: =$I38 -> 0
A39: ✓ | B39: テスト | C39: PM・全体管理 | D39: テスト管理 | E39: テストフェーズの進捗・不具合管理・品質ゲート | F39: － | G39: =管理費率 -> 0.2 | H39: － | I39: =IF($A39="－",0,ROUND(SUMIFS($BJ:$BJ,$B:$B,$B39)*$G39,0)) -> 360000 | J39: =IF($A39="－",0,ROUND(SUMIFS($BI:$BI,$B:$B,$B39)*$G39,0)) -> 256000 | BH39: pm
A40: ✓ | B40: テスト | C40: テスト・検証 | D40: テスト計画・項目作成 | E40: テスト範囲・シナリオ・優先度の定義 | F40: － | G40: 5 | H40: QC | I40: =IF(OR($A40="－",$H40=""),0,IFERROR(ROUND($G40*VLOOKUP($H40,単価表,4,FALSE()),0),0)) -> 300000 | J40: =IF(OR($A40="－",$H40=""),0,IFERROR(ROUND($G40*VLOOKUP($H40,単価表,3,FALSE()),0),0)) -> 200000 | K40: 機能数より | L40: M | BH40: leaf | BI40: =$J40 -> 200000 | BJ40: =$I40 -> 300000
A41: ✓ | B41: テスト | C41: テスト・検証 | D41: 結合・システムテスト実施 | E41: 実施・不具合登録・再テスト・主要端末での実機確認 | F41: － | G41: 12 | H41: QC | I41: =IF(OR($A41="－",$H41=""),0,IFERROR(ROUND($G41*VLOOKUP($H41,単価表,4,FALSE()),0),0)) -> 720000 | J41: =IF(OR($A41="－",$H41=""),0,IFERROR(ROUND($G41*VLOOKUP($H41,単価表,3,FALSE()),0),0)) -> 480000 | K41: 実装工数の約 25% | L41: M | BH41: leaf | BI41: =$J41 -> 480000 | BJ41: =$I41 -> 720000
...

Sheet スケジュール
A1: 📅 スケジュール（全体・動的）
A2: 青いセル（開始日・人数・工数・開始ラグ・審査待ち日数）を変えると、開始/終了日・ガント・総期間が自動で動きます。工数が数式の工程は見積明細と連動（計上－にすると期間も自動短縮）。既定は「前の工程が終わったら次を開始」の直列（最長ケース）。並走・前倒しは開始ラグを上書き。
A4: ⚙ プロジェクト設定
A5: プロジェクト開始日 | B5: 46266
A6: 営業日/月 | B6: =営業日月 -> 20
A8: 👥 並走人数（役割ごと）
A9: 役割 | B9: 人数
A10: PM | B10: 1
A11: Dir | B11: 1
A12: SE | B12: 1
A13: デザイナー | B13: 1
A14: アプリ | B14: 1
A15: フロントエンド | B15: 1
A16: バックエンド | B16: 1
A17: オフショア | B17: 1
A18: QC | B18: 1
A19: - | B19: 1
A20: ※「-」＝役割未指定の工程（人数はこの行を使用）
A21: 📅 スケジュール表（自動計算）
K22: =EDATE(DATE(YEAR($B$5),MONTH($B$5),1),0) -> 46266 | L22: =EDATE(DATE(YEAR($B$5),MONTH($B$5),1),1) -> 46296 | M22: =EDATE(DATE(YEAR($B$5),MONTH($B$5),1),2) -> 46327 | N22: =EDATE(DATE(YEAR($B$5),MONTH($B$5),1),3) -> 46357 | O22: =EDATE(DATE(YEAR($B$5),MONTH($B$5),1),4) -> 46388 | P22: =EDATE(DATE(YEAR($B$5),MONTH($B$5),1),5) -> 46419 | Q22: =EDATE(DATE(YEAR($B$5),MONTH($B$5),1),6) -> 46447 | R22: =EDATE(DATE(YEAR($B$5),MONTH($B$5),1),7) -> 46478 | S22: =EDATE(DATE(YEAR($B$5),MONTH($B$5),1),8) -> 46508 | T22: =EDATE(DATE(YEAR($B$5),MONTH($B$5),1),9) -> 46539 | U22: =EDATE(DATE(YEAR($B$5),MONTH($B$5),1),10) -> 46569 | V22: =EDATE(DATE(YEAR($B$5),MONTH($B$5),1),11) -> 46600 | W22: =EDATE(DATE(YEAR($B$5),MONTH($B$5),1),12) -> 46631 | X22: =EDATE(DATE(YEAR($B$5),MONTH($B$5),1),13) -> 46661 | Y22: =EDATE(DATE(YEAR($B$5),MONTH($B$5),1),14) -> 46692 | Z22: =EDATE(DATE(YEAR($B$5),MONTH($B$5),1),15) -> 46722 | AA22: =EDATE(DATE(YEAR($B$5),MONTH($B$5),1),16) -> 46753 | AB22: =EDATE(DATE(YEAR($B$5),MONTH($B$5),1),17) -> 46784
A23: 工程 | B23: 担当 | C23: 役割 | D23: 工数(人日) | E23: 並走人数 | F23: 営業日 | G23: 開始ラグ(営業日) | H23: 開始日 | I23: 終了日 | J23: 必要月数 | K23: =TEXT(K22,"m月") -> 9月 | L23: =TEXT(L22,"m月") -> 10月 | M23: =TEXT(M22,"m月") -> 11月 | N23: =TEXT(N22,"m月") -> 12月 | O23: =TEXT(O22,"m月") -> 1月 | P23: =TEXT(P22,"m月") -> 2月 | Q23: =TEXT(Q22,"m月") -> 3月 | R23: =TEXT(R22,"m月") -> 4月 | ... AB23: =TEXT(AB22,"m月") -> 2月
A24: 要件定義 | B24: BS | C24: - | D24: =ROUND(SUMIFS(見積書!$G:$G,見積書!$B:$B,"要件定義",見積書!$BH:$BH,"leaf",見積書!$A:$A,"<>－"),1) -> 25 | E24: =MAX(1,IFERROR(VLOOKUP($C24,$A$10:$B$19,2,FALSE()),1)) -> 1 | F24: =IF(OR($D24=0,$D24="",$D24="－"),0,ROUNDUP($D24/$E24,0)) -> 25 | G24: 0 | H24: =WORKDAY($B$5-1,$G24+1) -> 46266 | I24: =IF($F24<=1,$H24,WORKDAY($H24,$F24-1)) -> 46300 | J24: =IF($F24=0,"－",ROUND($F24/$B$6,1)&"ヶ月") -> 1.3ヶ月
A25: デザイン | B25: BS | C25: - | D25: =ROUND(SUMIFS(見積書!$G:$G,見積書!$B:$B,"デザイン",見積書!$BH:$BH,"leaf",見積書!$A:$A,"<>－"),1) -> 31 | E25: =MAX(1,IFERROR(VLOOKUP($C25,$A$10:$B$19,2,FALSE()),1)) -> 1 | F25: =IF(OR($D25=0,$D25="",$D25="－"),0,ROUNDUP($D25/$E25,0)) -> 31 | G25: =$G24+$F24 -> 25 | H25: =WORKDAY($B$5-1,$G25+1) -> 46301 | I25: =IF($F25<=1,$H25,WORKDAY($H25,$F25-1)) -> 46343 | J25: =IF($F25=0,"－",ROUND($F25/$B$6,1)&"ヶ月") -> 1.6ヶ月
A26: 設計 | B26: BS | C26: - | D26: =ROUND(SUMIFS(見積書!$G:$G,見積書!$B:$B,"設計",見積書!$BH:$BH,"leaf",見積書!$A:$A,"<>－"),1) -> 31 | E26: =MAX(1,IFERROR(VLOOKUP($C26,$A$10:$B$19,2,FALSE()),1)) -> 1 | F26: =IF(OR($D26=0,$D26="",$D26="－"),0,ROUNDUP($D26/$E26,0)) -> 31 | G26: =$G25+$F25 -> 56 | H26: =WORKDAY($B$5-1,$G26+1) -> 46344 | I26: =IF($F26<=1,$H26,WORKDAY($H26,$F26-1)) -> 46386 | J26: =IF($F26=0,"－",ROUND($F26/$B$6,1)&"ヶ月") -> 1.6ヶ月
A27: 開発 | B27: BS | C27: - | D27: =ROUND(SUMIFS(見積書!$G:$G,見積書!$B:$B,"開発",見積書!$BH:$BH,"leaf",見積書!$A:$A,"<>－"),1) -> 69 | E27: =MAX(1,IFERROR(VLOOKUP($C27,$A$10:$B$19,2,FALSE()),1)) -> 1 | F27: =IF(OR($D27=0,$D27="",$D27="－"),0,ROUNDUP($D27/$E27,0)) -> 69 | G27: =$G26+$F26 -> 87 | H27: =WORKDAY($B$5-1,$G27+1) -> 46387 | I27: =IF($F27<=1,$H27,WORKDAY($H27,$F27-1)) -> 46483 | J27: =IF($F27=0,"－",ROUND($F27/$B$6,1)&"ヶ月") -> 3.5ヶ月
A28: テスト | B28: BS | C28: - | D28: =ROUND(SUMIFS(見積書!$G:$G,見積書!$B:$B,"テスト",見積書!$BH:$BH,"leaf",見積書!$A:$A,"<>－"),1) -> 28 | E28: =MAX(1,IFERROR(VLOOKUP($C28,$A$10:$B$19,2,FALSE()),1)) -> 1 | F28: =IF(OR($D28=0,$D28="",$D28="－"),0,ROUNDUP($D28/$E28,0)) -> 28 | G28: =$G27+$F27 -> 156 | H28: =WORKDAY($B$5-1,$G28+1) -> 46484 | I28: =IF($F28<=1,$H28,WORKDAY($H28,$F28-1)) -> 46521 | J28: =IF($F28=0,"－",ROUND($F28/$B$6,1)&"ヶ月") -> 1.4ヶ月
A29: リリース | B29: BS | C29: - | D29: =ROUND(SUMIFS(見積書!$G:$G,見積書!$B:$B,"リリース",見積書!$BH:$BH,"leaf",見積書!$A:$A,"<>－"),1) -> 6 | E29: =MAX(1,IFERROR(VLOOKUP($C29,$A$10:$B$19,2,FALSE()),1)) -> 1 | F29: =IF(OR($D29=0,$D29="",$D29="－"),0,ROUNDUP($D29/$E29,0)) -> 6 | G29: =$G28+$F28 -> 184 | H29: =WORKDAY($B$5-1,$G29+1) -> 46524 | I29: =IF($F29<=1,$H29,WORKDAY($H29,$F29-1)) -> 46531 | J29: =IF($F29=0,"－",ROUND($F29/$B$6,1)&"ヶ月") -> 0.3ヶ月
A30: 受入テスト（貴社にて実施） | B30: 貴社 | C30: - | D30: 0 | E30: =MAX(1,IFERROR(VLOOKUP($C30,$A$10:$B$19,2,FALSE()),1)) -> 1 | F30: 10 | G30: =$G29+$F29 -> 190 | H30: =WORKDAY($B$5-1,$G30+1) -> 46532 | I30: =IF($F30<=1,$H30,WORKDAY($H30,$F30-1)) -> 46545 | J30: =IF($F30=0,"－",ROUND($F30/$B$6,1)&"ヶ月") -> 0.5ヶ月
A31: ストア申請・審査待ち | B31: 審査待 | C31: - | D31: 0 | E31: =MAX(1,IFERROR(VLOOKUP($C31,$A$10:$B$19,2,FALSE()),1)) -> 1 | F31: 10 | G31: =$G30+$F30 -> 200 | H31: =WORKDAY($B$5-1,$G31+1) -> 46546 | I31: =IF($F31<=1,$H31,WORKDAY($H31,$F31-1)) -> 46559 | J31: =IF($F31=0,"－",ROUND($F31/$B$6,1)&"ヶ月") -> 0.5ヶ月
A32: リリース（本番公開） | B32: リリース | C32: - | D32: 0 | E32: =MAX(1,IFERROR(VLOOKUP($C32,$A$10:$B$19,2,FALSE()),1)) -> 1 | F32: 1 | G32: =$G31+$F31 -> 210 | H32: =WORKDAY($B$5-1,$G32+1) -> 46560 | I32: =IF($F32<=1,$H32,WORKDAY($H32,$F32-1)) -> 46560 | J32: =IF($F32=0,"－",ROUND($F32/$B$6,1)&"ヶ月") -> 0.1ヶ月
A34: 🏁 プロジェクト終了日 | H34: =MAX(I24:I32) -> 46560
A35: 総期間（営業日） | H35: =NETWORKDAYS($B$5,H34) -> 211
A36: 総期間（カ月） | H36: =ROUND(H35/$B$6,1)&"ヶ月" -> 10.6ヶ月
A38: 凡例: | H38: ※ ガントは 18 ヶ月分。超える場合は AB 列を右へコピー
B39: BS | C39: 共同 | D39: 貴社 | E39: 審査待 | F39: リリース
A41: ⏭ 次にやること: 総期間とリリース日を確認 → お客様向けの月次ガントは AI に「提出用スケジュール（HTML）を生成して」と依頼

Sheet ヒアリングシート
A1: 🗣 ヒアリングシート（観点チェック）— 人は「確認」に ✓ を付けるだけ
A2: 見積もりから分かる項目は AI が回答を事前記入済み（水色セル＝要確認・修正可）。全項目に回答する必要はありません。観点漏れ防止のため『確認』列に ✓ だけ付けてください（✓ で行の色が変わります）。
F3: ="確認済み "&COUNTIF($A$5:$A$58,"✓")&" / 54 項目" -> 確認済み 0 / 54 項目
A4: 確認 | B4: # | C4: カテゴリ | D4: 項目 | E4: 内容・目的 | F4: 回答（分かる範囲でOK）
B5: 1 | C5: プロジェクト基本情報 | D5: クライアント名 | E5: 【内容】正式名称、担当部署 【目的】見積書や契約書の宛先として必要。
B6: 2 | D6: アプリ名称(仮) | E6: 【内容】プロジェクトの仮称または正式名称 【目的】共通言語として使用するため。
B7: 3 | D7: システム化の背景 | E7: 【内容】なぜこのプロジェクトが必要になったのか。現状の課題。 【目的】プロジェクトの根本的な目的を理解し、最適な解決策を提案する。
B8: 4 | D8: プロジェクトの目的とゴール | E8: 【内容】このプロジェクトで達成したい具体的な成果(売上UP、効率化など)。 【目的】機能の優先順位付けや、成功を定義する上での基準とする。
B9: 5 | D9: RFP(提案依頼書)の有無 | E9: 【内容】プロジェクトの目的や要件がまとまった公式な資料の有無。 【目的】要求事項の明確度を判断し、初期の要件整理工数を見積もるため。
B10: 6 | D10: 技術的な実現可能性の調査(PoC)の要否 | E10: 【内容】AI、画像解析、特殊なハードウェア連携など、技術的に不確実性の高い機能はあるか。 【目的】本開発とは別で、小規模な試作(PoC)による実現性検証が必要か判断する。本開発の見積もりとは別の工数・費用となるため、最初に確認が必須。
B11: 7 | C11: 成功指標と計測 | D11: 成功指標(KGI/KPI) | E11: 【内容】このプロジェクトが成功したと判断する具体的な数値目標と達成時期 【目的】合意した達成基準を元に、機能の優先順位やスコープを判断・調整するため。「作って終わり」を防ぐ。
B12: 8 | D12: アクセス解析ツールの導入 | E12: 【内容】利用状況の分析(どの画面がよく見られているか、など)のために、専用のツールを導入するか。 【目的】解析ツールのSDK組み込みや、計測したいイベント(ボタンクリックなど)の設計・実装に追加の工数がかかるため。
B13: 9 | C13: 体制とガバナンス | D13: クライアント側専任担当者 | E13: 【内容】プロジェクトの窓口となる担当者の有無。 【目的】専任担当者がいない場合、コミュニケーションコストや意思決定の遅延が予想され、工数に影響する。
B14: 10 | D14: 意思決定プロセス | E14: 【内容】仕様変更や追加費用の承認は、誰が、どのようなプロセス(稟議など)で行うか。 【目的】承認階層やプロセスが複雑な場合、手戻りや意思決定の遅延がスケジュールに大きく影響するため、事前に把握しておく必要がある。
B15: 11 | C15: スコープ(機能要件) | D15: 機能一覧(マスト/ウォント) | E15: 【内容】実装したい機能の洗い出し。必須機能と希望機能を分けておく。 【目的】スコープ確定・見積もりの基礎とする。
B16: 12 | D16: 管理画面の有無 | E16: 【内容】運営者が使用する管理機能の要否。 【目的】「有」の場合、別アプリ相当の設計・開発・テスト工数が追加で必要になるため。 | F16: 有（管理画面を見積に計上）
B17: 13 | D17: アプリ内課金(IAP)/決済 | E17: 【内容】App Store/Google Play経由での課金や、クレジットカード決済などが必要か。 【目的】決済機能は審査が厳しく、返金ポリシーなどの運用ルール設計も必要になるため、プロジェクトの難易度と工数が大幅に増加する。 | F17: 有（決済/課金関連を計上）
B18: 14 | D18: マネタイズの軸 | E18: 【内容】アプリ内課金、広告、サブスクリプション、EC連携など、このサービスでどのように収益を上げる計画か。 【目的】収益化の方法は、決済機能の実装だけでなく、ユーザー導線やUI設計の根幹に関わるため。
B19: 15 | D19: CSVエクスポート機能の有無 | E19: 【内容】管理画面などから、データをCSVファイルとしてダウンロードする機能は必要か。 【目的】管理画面の「あるある機能」であり、データ抽出ロジックとファイル生成処理の実装が必要になるため、事前に確認が必要。
B20: 16 | D20: データ移行の有無 | E20: 【内容】既存システムから新システムへデータ(例：会員情報)を移行する必要があるか。 【目的】データの抽出、変換、投入(ETL)の設計とリハーサルに大きな工数がかかるため。
B21: 17 | D21: 端末権限の利用 | E21: 【内容】位置情報、カメラ、プッシュ通知など、スマートフォンの機能を利用するか。 【目的】各機能の利用許可を求めるUI設計と、ユーザーが拒否した場合の代替フローを設計する必要があるため。 | F21: 利用あり（例: プッシュ通知等を計上）
B22: 18 | C22: スコープ(非機能要件) | D22: 対応OS・デバイス | E22: 【内容】iOS/Android/PC/タブレットなど、どのデバイスで利用できるようにするか。 【目的】対応デバイスが増えるほど、それぞれの画面サイズに合わせた設計・実装・テスト工数が増加する。 | F22: 前提条件シート参照（iOS / Android 各直近 2 世代・主要端末（Web の場合は…）
B23: 19 | D23: サポート範囲(OS/ブラウザ) | E23: 【内容】各OSやブラウザのどのバージョンまでサポートするか。 【目的】サポート範囲が広い(古いバージョンを含む)ほど、テスト工数や古い環境への対応コストが増加する。
B24: 20 | D24: 性能目標 | E24: 【内容】「〇〇秒以内に表示」「同時に〇〇人がアクセスしても耐えられる」といった、速度や負荷に関する具体的な目標はあるか。 【目的】高い性能目標を達成するには、それに合わせたインフラ設計やアーキテクチャ選定が必要になり、コストに大きく影響するため。
B25: 21 | D25: オフライン対応の有無 | E25: 【内容】電波がない状態でも、一部機能が利用できるようにするか。 【目的】端末内にデータを保存・同期する複雑なロジックが必要になり、工数が大幅に増加するため。
B26: 22 | D26: 画面の向き(縦固定/横対応) | E26: 【内容】スマートフォンやタブレットを横向きにした際の表示に対応するか。 【目的】横向きは、レイアウトが崩れないように設計・実装する必要があるため、工数に直接影響する。「縦向き固定」と割り切るだけで、工数を削減できる。
B27: 23 | D27: 多言語対応の有無 | E27: 【内容】日本語以外に対応するか。対応する場合、どの言語か。 【目的】翻訳テキストの管理、言語ごとのレイアウト調整(文字長の変動)など、工数への影響が非常に大きいため。 | F27: 対象外（別途お見積もり）
B28: 24 | D28: 計画停止の有無 | E28: 【内容】24時間365日稼働が前提か、深夜帯などに計画的なメンテナンス停止が可能か。 【目的】無停止でのリリース(デプロイ)が求められる場合、サーバー構成やリリース手順が複雑になり、工数が増加するため。
B29: 25 | C29: デザイン・体制 | D29: デザイン作成の担当 | E29: 【内容】デザイン(UI/UX)はどちらが用意するか(顧客支給 or 自社制作)。 【目的】自社でUIデザイン、UX設計から行う場合、工数が大幅に増加する。 | F29: 自社制作想定（UI/UXデザインを見積に計上）
B30: 26 | D30: 参考にしているサービス | E30: 【内容】デザインや機能のイメージに近い、参考となるアプリやWebサイト。 【目的】お客様の頭の中にある完成イメージを具体的に共有してもらうことで、デザインの方向性を固め、手戻りを防ぐ。
B31: 27 | D31: デザインのテーマカラー | E31: 【内容】ブランドカラーや、希望するメインカラー、アクセントカラー。 【目的】デザインの基調となる色を早期に決定することで、デザイン制作をスムーズに進めるため。
B32: 28 | D32: フォントの指定 | E32: 【内容】OS標準のフォント以外に、特定のブランドフォントや有償フォントを使用するか。 【目的】有償フォントを利用する場合、ライセンス費用の確認と、アプリへの組み込み工数が別途発生する。
B33: 29 | D33: スプラッシュ画面のアニメーション有無 | E33: 【内容】アプリ起動時に表示される画面(スプラッシュ)に、単純なロゴ表示だけでなく、アニメーションを実装するか。 【目的】アニメーションは、デザイン工数と実装工数の両方が追加で発生する。ブランディングに関わる重要な要素だが、コスト要因でもあるため確認が必要。
B34: 30 | D34: 素材の提供の有無 | E34: 【内容】アプリ内で使用する画像、テキスト、動画などの素材は誰が用意するか。 【目的】素材(特に原稿)の提供が遅れると、プロジェクト全体の遅延に直結する。
B35: 31 | D35: アクセシビリティ対応 | E35: 【内容】公共機関の案件などで、WCAGなどのアクセシビリティ基準に準拠する必要があるか。 【目的】音声読み上げ対応や、十分なコントラスト比の確保など、専門的な設計・実装・テストが必要になり、工数が大幅に増加するため。
B36: 32 | C36: インフラ・セキュリティ | D36: 個人情報の取り扱いの有無 | E36: 【内容】氏名、住所、電話番号、決済情報などを扱うか。 【目的】「有」の場合、セキュリティ要件が格段に上がり、暗号化やアクセス制御など厳重な設計・実装が必要。 | F36: 取り扱いあり想定（認証・セキュリティ設計を計上）
B37: 33 | D37: 権限管理・認可設計 | E37: 【内容】ユーザーの種類(管理者、一般ユーザー等)によって、使える機能や見られるデータを制御する必要があるか。 【目的】権限管理は設計・実装が複雑になりがちで、工数に大きく影響するため。
B38: 34 | D38: 監査ログ・操作ログの要否 | E38: 【内容】「誰が、いつ、何をしたか」といった操作履歴を保存する必要があるか。 【目的】ログの保存要件(何を、どのくらいの期間)は、サーバーのストレージコストや、ログ収集・解析基盤の構築工数に直接影響するため。
B39: 35 | D39: 脆弱性診断の実施有無 | E39: 【内容】第三者機関によるセキュリティの専門的な検査(脆弱性診断)を実施するか。 【目的】診断の実施費用(実費)と、検出された脆弱性の改修対応に大きな工数がかかる可能性があるため。 | F39: 実施（脆弱性診断を計上）
B40: 36 | D40: バックアップ/DR計画 | E40: 【内容】災害などでシステムが停止した場合、どのくらいの時間で復旧させる必要があるか。(RTO/RPO) 【目的】高い事業継続性を求める場合、バックアップやDR(災害復旧)サイトの構築・維持に専門的な工数とインフラコストがかかるため。
...

Sheet 非機能要件チェック
A1: 🛡 非機能要件チェック（Rule 2: 機能だけ数えて非機能を抜かさない）
A2: ="判定の進み具合: 対象 "&COUNTIF($E$4:$E$32,"対象")&" 件（うち明細未反映 "&COUNTIFS($E$4:$E$32,"対象",$F$4:$F$32,"")&" 件）／ 対象外 "&COUNTIF($E$4:$E$32,"対象外")&" 件 ／ 要確認 "&COUNTIF($E$4:$E$32,"要確認")&" 件 ／ 未判定 "&COUNTBLANK($E$4:$E$32)&" 件 ※ 最低 C(セキュリティ)・D(運用)・G1(ストア審査) は必ず判断（抜けやすい筆頭）" -> 判定の進み具合: 対象 0 件（うち明細未反映 0 件）／ 対象外 0 件 ／ 要確認 0 件 ／ 未判定 29 件 ※ 最低 C(セキュリティ)・D(運用)・G1(ストア審査) は必ず判断（抜けやすい筆頭）
A3: # | B3: 区分 | C3: チェック観点 | D3: 対象分野 | E3: 判定 | F3: 見積明細への反映（項目名） | G3: メモ（目標値・理由）
A4: A1 | B4: A. 性能・効率性 | C4: 画面表示・API レスポンス目標（例: 主要画面 2 秒以内） | D4: 共通
A5: A2 | B5: A. 性能・効率性 | C5: 同時接続・ピーク負荷（想定ユーザー数・イベント時の集中） | D5: サーバ・インフラ
A6: A3 | B6: A. 性能・効率性 | C6: データ量・件数の上限（一覧の件数・画像/動画サイズ） | D6: API・サーバ
A7: A4 | B7: A. 性能・効率性 | C7: 負荷テスト・チューニングの要否 | D7: サーバ・インフラ
A8: B1 | B8: B. 可用性・信頼性 | C8: 稼働率（SLA）・メンテナンス時間 | D8: インフラ
A9: B2 | B9: B. 可用性・信頼性 | C9: 障害時の復旧（バックアップ・リストア・冗長化） | D9: インフラ
A10: B3 | B10: B. 可用性・信頼性 | C10: データ整合性（決済・在庫など金銭/重要データ） | D10: API・サーバ
A11: C1 | B11: C. セキュリティ | C11: 認証・認可（ログイン方式・権限・多要素・SSO） | D11: 共通
A12: C2 | B12: C. セキュリティ | C12: 個人情報・機微情報の取扱い（暗号化・マスキング） | D12: API・サーバ
A13: C3 | B13: C. セキュリティ | C13: 決済・金銭処理のセキュリティ（PCI DSS 等） | D13: API・サーバ
A14: C4 | B14: C. セキュリティ | C14: 脆弱性診断・対応（リリース前診断の要否） | D14: 共通
A15: C5 | B15: C. セキュリティ | C15: 通信の暗号化・証明書・WAF | D15: インフラ
... A32: H2 | B32: H. 分析・計測 | C32: KPI ダッシュボード・レポート | D32: 管理画面
A34: ⏭ 次にやること: 「対象」にした観点は見積明細に工数を積んで F 列に項目名を記入 → 「対象外」は提出物の前提（対象外）に明記 → 「要確認」は AI に ❓ で確認を依頼
